<title>Issue 10608 -   chromium -    Random issues with ssl tests - Project Hosting on Google Code</title> <pre> In net/base/ssl_test_util.cc  TestServerLauncher::Start() seems to fail occasionally under load. See an example on the mac:     [----------] 2 tests from URLFetcherTest  [ RUN      ] URLFetcherTest.SameThreadsTest  [81779:267:0416/132701:95243185712011:INFO:/Users/maruel/code/b/slave/mac/build/src/net/base/ssl_test_util.cc(225)] Trying to launch python ...  /Users/maruel/code/b/pylibs/zope/__init__.py:19: UserWarning: Module zope was already imported from /Users/maruel/code/b/pylibs/zope/__init__.pyc  but   /System/Library/Frameworks/Python.framework/Versions/2.5/Extras/lib/python is being added to sys.path    import pkg_resources  [81779:267:0416/132703:95245188032628:INFO:/Users/maruel/code/b/slave/mac/build/src/net/base/ssl_test_util.cc(241)] Started on port 1337  [81779:267:0416/132704:95246197578965:INFO:/Users/maruel/code/b/slave/mac/build/src/net/base/ssl_test_util.cc(282)] Stopped.  [       OK ] URLFetcherTest.SameThreadsTest (3013 ms)  [ RUN      ] URLFetcherTest.DifferentThreadsTest  [81779:267:0416/132704:95246197886654:INFO:/Users/maruel/code/b/slave/mac/build/src/net/base/ssl_test_util.cc(225)] Trying to launch python ...  /Users/maruel/code/b/pylibs/zope/__init__.py:19: UserWarning: Module zope was already imported from /Users/maruel/code/b/pylibs/zope/__init__.pyc  but   /System/Library/Frameworks/Python.framework/Versions/2.5/Extras/lib/python is being added to sys.path    import pkg_resources  [81779:267:0416/132712:95254202404465:INFO:/Users/maruel/code/b/slave/mac/build/src/net/base/ssl_test_util.cc(241)] Started on port 1337  [81779:267:0416/132713:95255352077414:INFO:/Users/maruel/code/b/slave/mac/build/src/net/base/ssl_test_util.cc(282)] Stopped.  [       OK ] URLFetcherTest.DifferentThreadsTest (9154 ms)  [----------] 2 tests from URLFetcherTest (12167 ms total)    [----------] 1 test from URLFetcherPostTest  [ RUN      ] URLFetcherPostTest.Basic  [81779:267:0416/132713:95255352336201:INFO:/Users/maruel/code/b/slave/mac/build/src/net/base/ssl_test_util.cc(225)] Trying to launch python ...  /Users/maruel/code/b/pylibs/zope/__init__.py:19: UserWarning: Module zope was already imported from /Users/maruel/code/b/pylibs/zope/__init__.pyc  but   /System/Library/Frameworks/Python.framework/Versions/2.5/Extras/lib/python is being added to sys.path    import pkg_resources  [81779:267:0416/132723:95265357448215:ERROR:/Users/maruel/code/b/slave/mac/build/src/net/base/ssl_test_util.cc(236)] Failed to connect to server  [81779:267:0416/132724:95266357532170:INFO:/Users/maruel/code/b/slave/mac/build/src/net/base/ssl_test_util.cc(282)] Stopped.  /Users/maruel/code/b/slave/mac/build/src/chrome/browser/net/url_fetcher_unittest.cc:369: Failure  Value of: NULL != server.get()    Actual: false  Expected: true  [  FAILED  ] URLFetcherPostTest.Basic (11005 ms)  [----------] 1 test from URLFetcherPostTest (11005 ms total)      My take is simply that the web server from the previous test wasn't fully shut down causing the next one to be unable to start. Note the very long test times (&gt; 10 sec) </pre>